# Generated by Django 4.2.7 on 2025-10-06 16:33

from django.db import migrations, models


class Migration(migrations.Migration):

    dependencies = [
        ('businesses', '0005_add_city_slug_unique_constraint'),
    ]

    operations = [
        migrations.AddIndex(
            model_name='business',
            index=models.Index(fields=['name', 'city'], name='businesses__name_4bfc36_idx'),
        ),
        migrations.AddIndex(
            model_name='business',
            index=models.Index(fields=['email', 'city'], name='businesses__email_486f02_idx'),
        ),
        migrations.AddIndex(
            model_name='business',
            index=models.Index(fields=['phone', 'city'], name='businesses__phone_e1f5e7_idx'),
        ),
        migrations.AddConstraint(
            model_name='business',
            constraint=models.UniqueConstraint(fields=('name', 'city'), name='unique_business_name_city', violation_error_message='A business with this name already exists in this city.'),
        ),
        migrations.AddConstraint(
            model_name='business',
            constraint=models.UniqueConstraint(condition=models.Q(('email__isnull', False), models.Q(('email', ''), _negated=True)), fields=('email', 'city'), name='unique_business_email_city', violation_error_message='A business with this email already exists in this city.'),
        ),
        migrations.AddConstraint(
            model_name='business',
            constraint=models.UniqueConstraint(condition=models.Q(('phone__isnull', False), models.Q(('phone', ''), _negated=True)), fields=('phone', 'city'), name='unique_business_phone_city', violation_error_message='A business with this phone number already exists in this city.'),
        ),
    ]
